<?xml version="1.0" encoding="UTF-8"?>
<robot name="s2_v1">
  <joint name="L_ankle_pitch_joint" type="revolute">
    <origin xyz="0. -0.3700001 0. " rpy="0. 0. 0."/>
    <parent link="L_knee_pitch_link"/>
    <child link="L_ankle_pitch_link"/>
    <axis xyz="0. 0. 1."/>
    <limit lower="-0.5235" upper="1.0470999" effort="60." velocity="8.7265994"/>
  </joint>
  <joint name="L_ankle_roll_joint" type="revolute">
    <origin xyz="0. -0.0000001 0. " rpy="1.5708 0.0000001 1.5708 "/>
    <parent link="L_ankle_pitch_link"/>
    <child link="L_ankle_roll_link"/>
    <axis xyz="0. 0. 1."/>
    <limit lower="-0.5235" upper="0.5235" effort="60." velocity="8.7265994"/>
  </joint>
  <joint name="L_elbow_roll_joint" type="revolute">
    <origin xyz="-0.019993 0. 0.213 " rpy="-1.5708001 0. -0. "/>
    <parent link="L_shoulder_yaw_link"/>
    <child link="L_elbow_roll_link"/>
    <axis xyz="0. 0. 1."/>
    <limit lower="-2.6528999" upper="0.0349" effort="45." velocity="3.1415998"/>
  </joint>
  <joint name="L_elbow_yaw_joint" type="revolute">
    <origin xyz="0.019993 -0.10368 0. " rpy="1.5707998 -0.0000001 0. "/>
    <parent link="L_elbow_roll_link"/>
    <child link="L_elbow_yaw_link"/>
    <axis xyz="0. 0. 1."/>
    <limit lower="-2.9321997" upper="2.9321997" effort="20." velocity="3.1415998"/>
  </joint>
  <joint name="L_hip_pitch_joint" type="revolute">
    <origin xyz="-0. 0. 0.122" rpy="-1.5708 -0.0000001 0. "/>
    <parent link="L_hip_yaw_link"/>
    <child link="L_hip_pitch_link"/>
    <axis xyz="0. 0. 1."/>
    <limit lower="-0.349" upper="1.9198" effort="200." velocity="8.7265994"/>
  </joint>
  <joint name="L_hip_roll_joint" type="revolute">
    <origin xyz="0. 0.105 0. " rpy="3.1415927 1.5707927 3.1415927"/>
    <parent link="s2_v1"/>
    <child link="L_hip_roll_link"/>
    <axis xyz="0. 0. 1."/>
    <limit lower="-0.4363" upper="0.7853" effort="220." velocity="3.1415998"/>
  </joint>
  <joint name="L_hip_yaw_joint" type="revolute">
    <origin xyz="0. 0. 0." rpy="-1.5569803 -1.5707927 -1.5846052"/>
    <parent link="L_hip_roll_link"/>
    <child link="L_hip_yaw_link"/>
    <axis xyz="0. 0. 1."/>
    <limit lower="-0.7853" upper="1.0470999" effort="60." velocity="5.236"/>
  </joint>
  <joint name="L_knee_pitch_joint" type="revolute">
    <origin xyz="0. -0.36 0.0000001" rpy="-0.0000002 0. 0. "/>
    <parent link="L_hip_pitch_link"/>
    <child link="L_knee_pitch_link"/>
    <axis xyz="0. 0. 1."/>
    <limit lower="-2.2688998" upper="0.0872" effort="250." velocity="9.5993002"/>
  </joint>
  <joint name="L_shoulder_pitch_joint" type="revolute">
    <origin xyz="-0. 0.15387 0. " rpy="3.1415925 -1.3962625 -1.5707927"/>
    <parent link="torso_link"/>
    <child link="L_shoulder_pitch_link"/>
    <axis xyz="0. 0. 1."/>
    <limit lower="-2.8622998" upper="2.8622998" effort="80." velocity="3.1415998"/>
  </joint>
  <joint name="L_shoulder_roll_joint" type="revolute">
    <origin xyz="-0. -0. -0.06" rpy="-1.5708 0. -0. "/>
    <parent link="L_shoulder_pitch_link"/>
    <child link="L_shoulder_roll_link"/>
    <axis xyz="0. 0. 1."/>
    <limit lower="-1.8849999" upper="0.1222" effort="80." velocity="3.1415998"/>
  </joint>
  <joint name="L_shoulder_yaw_joint" type="revolute">
    <origin xyz="-0.083 -0. 0. " rpy="-1.5707998 -0.0000001 1.5708 "/>
    <parent link="L_shoulder_roll_link"/>
    <child link="L_shoulder_yaw_link"/>
    <axis xyz="0. 0. 1."/>
    <limit lower="-2.9321997" upper="2.9321997" effort="45." velocity="3.1415998"/>
  </joint>
  <joint name="L_sixforce_joint" type="fixed">
    <origin xyz="0. 0.29712 0. " rpy="-0.0000002 -0.0000036 -1.5708003"/>
    <parent link="L_wrist_roll_link"/>
    <child link="L_sixforce_link"/>
  </joint>
  <joint name="L_wrist_pitch_joint" type="revolute">
    <origin xyz="-0. -0. 0.11832" rpy="-0.0276714 1.5707927 3.113914 "/>
    <parent link="L_elbow_yaw_link"/>
    <child link="L_wrist_pitch_link"/>
    <axis xyz="0. 0. 1."/>
    <limit lower="-1.6579999" upper="1.6579999" effort="20." velocity="3.1415998"/>
  </joint>
  <joint name="L_wrist_roll_joint" type="revolute">
    <origin xyz="-0.076 0. 0. " rpy="-1.5827596 1.5707928 -0.0119598"/>
    <parent link="L_wrist_pitch_link"/>
    <child link="L_wrist_roll_link"/>
    <axis xyz="0. 0. 1."/>
    <limit lower="-2.0244998" upper="2.0244998" effort="20." velocity="3.1415998"/>
  </joint>
  <joint name="R_ankle_pitch_joint" type="revolute">
    <origin xyz="0. -0.3700001 0. " rpy="0. 0. 0."/>
    <parent link="R_knee_pitch_link"/>
    <child link="R_ankle_pitch_link"/>
    <axis xyz="0. 0. 1."/>
    <limit lower="-0.5235" upper="1.0470999" effort="60." velocity="8.7265994"/>
  </joint>
  <joint name="R_ankle_roll_joint" type="revolute">
    <origin xyz="0. -0.0000001 0. " rpy="1.5708 0.0000001 1.5708 "/>
    <parent link="R_ankle_pitch_link"/>
    <child link="R_ankle_roll_link"/>
    <axis xyz="0. 0. 1."/>
    <limit lower="-0.5235" upper="0.5235" effort="60." velocity="8.7265994"/>
  </joint>
  <joint name="R_elbow_roll_joint" type="revolute">
    <origin xyz="-0.019989 -0.0004003 0.213 " rpy="-1.5708 -0.0000001 0.020023 "/>
    <parent link="R_shoulder_yaw_link"/>
    <child link="R_elbow_roll_link"/>
    <axis xyz="0. 0. 1."/>
    <limit lower="-2.6528999" upper="0.0349" effort="45." velocity="3.1415998"/>
  </joint>
  <joint name="R_elbow_yaw_joint" type="revolute">
    <origin xyz="0.019993 -0.10368 -0. " rpy="1.5708 0. -0. "/>
    <parent link="R_elbow_roll_link"/>
    <child link="R_elbow_yaw_link"/>
    <axis xyz="0. 0. 1."/>
    <limit lower="-2.9321997" upper="2.9321997" effort="20." velocity="3.1415998"/>
  </joint>
  <joint name="R_hip_pitch_joint" type="revolute">
    <origin xyz="-0. 0. 0.122" rpy="-1.5708 -0.0000001 0. "/>
    <parent link="R_hip_yaw_link"/>
    <child link="R_hip_pitch_link"/>
    <axis xyz="0. 0. 1."/>
    <limit lower="-0.349" upper="1.9198" effort="200." velocity="8.7265994"/>
  </joint>
  <joint name="R_hip_roll_joint" type="revolute">
    <origin xyz="0. -0.105 0. " rpy="3.1415927 1.5707927 3.1415927"/>
    <parent link="s2_v1"/>
    <child link="R_hip_roll_link"/>
    <axis xyz="0. 0. 1."/>
    <limit lower="-0.7853" upper="0.4363" effort="220." velocity="3.1415998"/>
  </joint>
  <joint name="R_hip_yaw_joint" type="revolute">
    <origin xyz="0. 0. 0." rpy="-1.5569803 -1.5707927 -1.5846052"/>
    <parent link="R_hip_roll_link"/>
    <child link="R_hip_yaw_link"/>
    <axis xyz="0. 0. 1."/>
    <limit lower="-1.0470999" upper="0.7853" effort="60." velocity="5.236"/>
  </joint>
  <joint name="R_knee_pitch_joint" type="revolute">
    <origin xyz="0. -0.36 0.0000001" rpy="-0.0000002 0. 0. "/>
    <parent link="R_hip_pitch_link"/>
    <child link="R_knee_pitch_link"/>
    <axis xyz="0. 0. 1."/>
    <limit lower="-2.2688998" upper="0.0872" effort="250." velocity="9.5993002"/>
  </joint>
  <joint name="R_shoulder_pitch_joint" type="revolute">
    <origin xyz="-0. -0.15387 -0. " rpy="-3.1415856 -1.3962702 1.5708003"/>
    <parent link="torso_link"/>
    <child link="R_shoulder_pitch_link"/>
    <axis xyz="0. 0. 1."/>
    <limit lower="-2.8622998" upper="2.8622998" effort="80." velocity="3.1415998"/>
  </joint>
  <joint name="R_shoulder_roll_joint" type="revolute">
    <origin xyz="-0. -0. -0.06" rpy="-1.5708 -0. -0. "/>
    <parent link="R_shoulder_pitch_link"/>
    <child link="R_shoulder_roll_link"/>
    <axis xyz="0. 0. 1."/>
    <limit lower="-1.8849999" upper="0.1222" effort="80." velocity="3.1415998"/>
  </joint>
  <joint name="R_shoulder_yaw_joint" type="revolute">
    <origin xyz="-0.083 -0. 0. " rpy="-1.5708 -0.0200231 1.5708 "/>
    <parent link="R_shoulder_roll_link"/>
    <child link="R_shoulder_yaw_link"/>
    <axis xyz="0. 0. 1."/>
    <limit lower="-2.9321997" upper="2.9321997" effort="45." velocity="3.1415998"/>
  </joint>
  <joint name="R_sixforce_joint" type="fixed">
    <origin xyz="0. 0.29712 -0. " rpy="3.1415892 0.0000002 -1.5707927"/>
    <parent link="R_wrist_roll_link"/>
    <child link="R_sixforce_link"/>
  </joint>
  <joint name="R_wrist_pitch_joint" type="revolute">
    <origin xyz="-0. -0. 0.11832" rpy="0.001654 1.5707927 -3.139946 "/>
    <parent link="R_elbow_yaw_link"/>
    <child link="R_wrist_pitch_link"/>
    <axis xyz="0. 0. 1."/>
    <limit lower="-1.6579999" upper="1.6579999" effort="20." velocity="3.1415998"/>
  </joint>
  <joint name="R_wrist_roll_joint" type="revolute">
    <origin xyz="-0.076 -0. -0. " rpy="-1.5329862 1.5707927 0.0378137"/>
    <parent link="R_wrist_pitch_link"/>
    <child link="R_wrist_roll_link"/>
    <axis xyz="0. 0. 1."/>
    <limit lower="-2.0244998" upper="2.0244998" effort="20." velocity="3.1415998"/>
  </joint>
  <joint name="head_pitch_joint" type="revolute">
    <origin xyz="0. 0. 0.025" rpy="1.5708 0. 0. "/>
    <parent link="head_yaw_link"/>
    <child link="head_pitch_link"/>
    <axis xyz="0. 0. 1."/>
    <limit lower="-0.7854" upper="0.5235999" effort="4.5" velocity="3.1415998"/>
  </joint>
  <joint name="head_yaw_joint" type="revolute">
    <origin xyz="-0. -0. 0.13546" rpy="0.0000001 0. 0. "/>
    <parent link="torso_link"/>
    <child link="head_yaw_link"/>
    <axis xyz="0. 0. 1."/>
    <limit lower="-1.6579999" upper="1.6579999" effort="4.5" velocity="3.1415998"/>
  </joint>
  <joint name="joint_head_pitch_link-head_fisheye_left_Camera" type="fixed">
    <origin xyz="0.02704 0.10455 -0.07967" rpy="-0.0000001 0. 0. "/>
    <parent link="head_pitch_link"/>
    <child link="head_fisheye_left_Camera"/>
  </joint>
  <joint name="joint_head_pitch_link-head_fisheye_right_Camera" type="fixed">
    <origin xyz="0.02704 0.10455 0.07967" rpy="-3.1415925 0. -3.1415927"/>
    <parent link="head_pitch_link"/>
    <child link="head_fisheye_right_Camera"/>
  </joint>
  <joint name="joint_head_pitch_link-head_pitch_link_head_imu_head_imu" type="fixed">
    <origin xyz="0. -0. 0." rpy="-0.0000001 0. 0. "/>
    <parent link="head_pitch_link"/>
    <child link="head_pitch_link_head_imu_head_imu"/>
  </joint>
  <joint name="joint_head_pitch_link-head_stereo_left_Camera_01" type="fixed">
    <origin xyz="0.10704 0.13247 -0.03199" rpy="0. -1.5707963 0. "/>
    <parent link="head_pitch_link"/>
    <child link="head_stereo_left_Camera_01"/>
  </joint>
  <joint name="joint_head_pitch_link-head_stereo_right_Camera_01" type="fixed">
    <origin xyz="0.10704 0.13247 0.03199" rpy="0. -1.5707963 0. "/>
    <parent link="head_pitch_link"/>
    <child link="head_stereo_right_Camera_01"/>
  </joint>
  <joint name="joint_s2_v1-base_link_body_imu_body_imu" type="fixed">
    <origin xyz="0. 0. 0." rpy="0. 0. 0."/>
    <parent link="s2_v1"/>
    <child link="base_link_body_imu_body_imu"/>
  </joint>
  <joint name="joint_s2_v1-waist_front_cam_Camera" type="fixed">
    <origin xyz="0.0767722 0. -0.00745 " rpy="0.7744216 0. -1.5707964"/>
    <parent link="s2_v1"/>
    <child link="waist_front_cam_Camera"/>
  </joint>
  <joint name="joint_waist_pitch_link-back_rear_cam_Camera" type="fixed">
    <origin xyz="-0.1544154 0.31245 -0. " rpy="-0.7965857 1.5707963 0. "/>
    <parent link="waist_pitch_link"/>
    <child link="back_rear_cam_Camera"/>
  </joint>
  <joint name="torso_waist_joint" type="fixed">
    <origin xyz="-0.0046 0.34864 -0. " rpy="-1.5708 0. 0. "/>
    <parent link="waist_pitch_link"/>
    <child link="torso_link"/>
  </joint>
  <joint name="waist_pitch_joint" type="revolute">
    <origin xyz="0. 0. 0." rpy="-1.5708 0. 0. "/>
    <parent link="waist_yaw_link"/>
    <child link="waist_pitch_link"/>
    <axis xyz="0. 0. 1."/>
    <limit lower="-1.5706999" upper="0.6108" effort="265." velocity="2.0943998"/>
  </joint>
  <joint name="waist_yaw_joint" type="revolute">
    <origin xyz="0. 0. 0.143" rpy="-3.1415854 0. 0. "/>
    <parent link="s2_v1"/>
    <child link="waist_yaw_link"/>
    <axis xyz="0. 0. 1."/>
    <limit lower="-2.8273998" upper="2.8273998" effort="85." velocity="3.1415998"/>
  </joint>
  <link name="L_ankle_pitch_link">
    <inertial>
      <origin xyz="0. 0. 0." rpy="0. 0. 0."/>
      <mass value="0.065914"/>
      <inertia ixx="0.0000109" ixy="-0." ixz="0." iyy="0.0000184" iyz="0." izz="0.0000109"/>
    </inertial>
    <visual>
      <origin xyz="0.7291621 -0.0004683 -0.1053393" rpy="1.5707964 1.5707964 0. "/>
      <geometry>
        <mesh filename="file:///home/ubt/Documents/gitlab/images/ecbg/assets/meshes/L_ankle_pitch_link_ankle_pitch_01.obj" scale="1. 1. 1."/>
      </geometry>
    </visual>
  </link>
  <link name="L_ankle_roll_link">
    <inertial>
      <origin xyz="-0.12 -0.000273 0.023974" rpy="0. 0. 0."/>
      <mass value="0.78306"/>
      <inertia ixx="0.0032684" ixy="-0.0000022" ixz="0.000163" iyy="0.0028805" iyz="-0.0000078" izz="0.0007011"/>
    </inertial>
    <visual>
      <origin xyz="0.7317544 -0.1040706 0.0010781" rpy="0.0000001 -0. -1.5707961"/>
      <geometry>
        <mesh filename="file:///home/ubt/Documents/gitlab/images/ecbg/assets/meshes/L_ankle_roll_link_ankle_roll_01.obj" scale="1. 1. 1."/>
      </geometry>
    </visual>
    <visual>
      <origin xyz="-0.034 -0. 0.045" rpy="-0. -0.0000001 0.0000002"/>
      <geometry>
        <box size="0.03 0.12 0.26"/>
      </geometry>
    </visual>
    <collision>
      <origin xyz="-0.034 -0. 0.045" rpy="-0. -0.0000001 0.0000002"/>
      <geometry>
        <box size="0.03 0.12 0.26"/>
      </geometry>
    </collision>
  </link>
  <link name="L_elbow_roll_link">
    <inertial>
      <origin xyz="0.0085304 -0.05741 0.0008927" rpy="0. 0. 0."/>
      <mass value="0.6675"/>
      <inertia ixx="0.0025384" ixy="0.0003061" ixz="0.0000075" iyy="0.0013951" iyz="-0.0000335" izz="0.002205"/>
    </inertial>
    <visual>
      <origin xyz="-0.2694288 -0.3047038 0.003215 " rpy="-0.0000001 -0.0000001 -0.122173 "/>
      <geometry>
        <mesh filename="file:///home/ubt/Documents/gitlab/images/ecbg/assets/meshes/L_elbow_roll_01.obj" scale="1. 1. 1."/>
      </geometry>
    </visual>
  </link>
  <link name="L_elbow_yaw_link">
    <inertial>
      <origin xyz="0.0009741 0.0001793 0.045777 " rpy="0. 0. 0."/>
      <mass value="0.87457"/>
      <inertia ixx="0.0014384" ixy="0.0000039" ixz="-0.0000522" iyy="0.0016363" iyz="0.0000007" izz="0.0008758"/>
    </inertial>
    <visual>
      <origin xyz="-0.2944977 0.0050625 0.1965348" rpy="-1.5707963 -0.1396263 -0.0000001"/>
      <geometry>
        <mesh filename="file:///home/ubt/Documents/gitlab/images/ecbg/assets/meshes/L_elbow_yaw_01.obj" scale="1. 1. 1."/>
      </geometry>
    </visual>
  </link>
  <link name="L_hip_pitch_link">
    <inertial>
      <origin xyz="0.0018469 -0.1559 -0.0026939" rpy="0. 0. 0."/>
      <mass value="4.1506"/>
      <inertia ixx="0.04292" ixy="0.00183" ixz="0.0000639" iyy="0.0099854" iyz="-0.001123" izz="0.042785"/>
    </inertial>
    <visual>
      <origin xyz="-0.0050444 0.0070958 0.1036926" rpy="-1.5707957 1.5707961 -1.5707957"/>
      <geometry>
        <mesh filename="file:///home/ubt/Documents/gitlab/images/ecbg/assets/meshes/L_hip_pitch_01.obj" scale="1. 1. 1."/>
      </geometry>
    </visual>
  </link>
  <link name="L_hip_roll_link">
    <inertial>
      <origin xyz="0.0092362 0.0006846 -0.0076246" rpy="0. 0. 0."/>
      <mass value="1.3211"/>
      <inertia ixx="0.001866" ixy="0.0000152" ixz="-0.000098" iyy="0.0017359" iyz="0.0000252" izz="0.0011634"/>
    </inertial>
    <visual>
      <origin xyz="0.12282 0.1055 0. " rpy="-0.0000001 0. 1.5707964"/>
      <geometry>
        <mesh filename="file:///home/ubt/Documents/gitlab/images/ecbg/assets/meshes/L_hip_roll_link_L_hip_roll_01.obj" scale="1. 1. 1."/>
      </geometry>
    </visual>
  </link>
  <link name="L_hip_yaw_link">
    <inertial>
      <origin xyz="0.0002397 0.0039636 0.11569 " rpy="0. 0. 0."/>
      <mass value="2.2890999"/>
      <inertia ixx="0.0043044" ixy="0.000004" ixz="-0.0000092" iyy="0.0048929" iyz="-0.000051" izz="0.0036277"/>
    </inertial>
    <visual>
      <origin xyz="-0.0004075 0.1051887 0.1218592" rpy="-1.5707964 -0. 1.5707964"/>
      <geometry>
        <mesh filename="file:///home/ubt/Documents/gitlab/images/ecbg/assets/meshes/L_hip_yaw_link_hip_yaw_01.obj" scale="1. 1. 1."/>
      </geometry>
    </visual>
  </link>
  <link name="L_knee_pitch_link">
    <inertial>
      <origin xyz="-0.0010047 -0.15955 0.0010045" rpy="0. 0. 0."/>
      <mass value="3.8269"/>
      <inertia ixx="0.034069" ixy="-0.000889" ixz="-0.0000685" iyy="0.0048648" iyz="-0.000151" izz="0.034816"/>
    </inertial>
    <visual>
      <origin xyz="-0.0014079 0.3632442 0.1047697" rpy="0. 1.5707964 0. "/>
      <geometry>
        <mesh filename="file:///home/ubt/Documents/gitlab/images/ecbg/assets/meshes/L_knee_pitch_01.obj" scale="1. 1. 1."/>
      </geometry>
    </visual>
  </link>
  <link name="L_shoulder_pitch_link">
    <inertial>
      <origin xyz="0.000221 -0.0050932 -0.05263 " rpy="0. 0. 0."/>
      <mass value="0.98147"/>
      <inertia ixx="0.0011759" ixy="-0.0000048" ixz="-0.0000024" iyy="0.0011237" iyz="-0.0000312" izz="0.0009004"/>
    </inertial>
    <visual>
      <origin xyz="-0.5875514 -0.0045995 0.254259 " rpy="-1.5707961 1.3962634 -3.1415925"/>
      <geometry>
        <mesh filename="file:///home/ubt/Documents/gitlab/images/ecbg/assets/meshes/L_should_pitch_01.obj" scale="1. 1. 1."/>
      </geometry>
    </visual>
  </link>
  <link name="L_shoulder_roll_link">
    <inertial>
      <origin xyz="-0.036346 0.0019751 -0.0052697" rpy="0. 0. 0."/>
      <mass value="0.53957"/>
      <inertia ixx="0.0012305" ixy="-0.000019" ixz="0.000107" iyy="0.0018915" iyz="-0.000013" izz="0.0014298"/>
    </inertial>
    <visual>
      <origin xyz="-0.6176085 -0.257444 -0.0056587" rpy="-3.1415925 -0. 1.6406095"/>
      <geometry>
        <mesh filename="file:///home/ubt/Documents/gitlab/images/ecbg/assets/meshes/L_should_roll_01.obj" scale="1. 1. 1."/>
      </geometry>
    </visual>
  </link>
  <link name="L_shoulder_yaw_link">
    <inertial>
      <origin xyz="-0.00899 0.00278 0.1286 " rpy="0. 0. 0."/>
      <mass value="1.9976"/>
      <inertia ixx="0.015656" ixy="0.000054" ixz="0.0015653" iyy="0.015768" iyz="-0.000436" izz="0.0021057"/>
    </inertial>
    <visual>
      <origin xyz="-0.2834035 0.0069502 0.517537 " rpy="-1.5707964 -0.122173 -0. "/>
      <geometry>
        <mesh filename="file:///home/ubt/Documents/gitlab/images/ecbg/assets/meshes/L_should_yaw_01.obj" scale="1. 1. 1."/>
      </geometry>
    </visual>
  </link>
  <link name="L_sixforce_link">
    <inertial>
      <origin xyz="0.0001862 0.0000021 -0.011066 " rpy="0. 0. 0."/>
      <mass value="0.17"/>
      <inertia ixx="0.0000357" ixy="0.0000002" ixz="-0.0000008" iyy="0.0000503" iyz="0.0000001" izz="0.0000613"/>
    </inertial>
  </link>
  <link name="L_wrist_pitch_link">
    <inertial>
      <origin xyz="-0.038445 -0.0048559 -0.0047721" rpy="0. 0. 0."/>
      <mass value="1.3145"/>
      <inertia ixx="0.0009004" ixy="-0.0002185" ixz="0.000227" iyy="0.0027314" iyz="0.0000305" izz="0.0027358"/>
    </inertial>
    <visual>
      <origin xyz="-0.0835025 -0.0017103 0.2947018" rpy="-1.5707953 1.4486231 -3.1415915"/>
      <geometry>
        <mesh filename="file:///home/ubt/Documents/gitlab/images/ecbg/assets/meshes/L_wrist_pitch_01.obj" scale="1. 1. 1."/>
      </geometry>
    </visual>
  </link>
  <link name="L_wrist_roll_link">
    <inertial>
      <origin xyz="-0.0000046 0.017056 -0.0007487" rpy="0. 0. 0."/>
      <mass value="0.1521"/>
      <inertia ixx="0.0002736" ixy="0." ixz="-0." iyy="0.0002155" iyz="-0.0000077" izz="0.0001102"/>
    </inertial>
    <visual>
      <origin xyz="-0.2952081 0.0096973 -0.0018446" rpy="-3.1415927 0.0000001 0.1221728"/>
      <geometry>
        <mesh filename="file:///home/ubt/Documents/gitlab/images/ecbg/assets/meshes/L_wrist_roll_01.obj" scale="1. 1. 1."/>
      </geometry>
    </visual>
  </link>
  <link name="R_ankle_pitch_link">
    <inertial>
      <origin xyz="0. 0. 0." rpy="0. 0. 0."/>
      <mass value="0.065914"/>
      <inertia ixx="0.0000109" ixy="0." ixz="0." iyy="0.0000184" iyz="0." izz="0.0000109"/>
    </inertial>
    <visual>
      <origin xyz="-0.728789 0.0000356 0.1069531" rpy="1.5707964 -1.5707964 0. "/>
      <geometry>
        <mesh filename="file:///home/ubt/Documents/gitlab/images/ecbg/assets/meshes/R_ankle_pitch_link_ankle_pitch_01.obj" scale="1. 1. 1."/>
      </geometry>
    </visual>
  </link>
  <link name="R_ankle_roll_link">
    <inertial>
      <origin xyz="-0.12 0.0002657 0.023951 " rpy="0. 0. 0."/>
      <mass value="0.78316"/>
      <inertia ixx="0.0032686" ixy="0.0000022" ixz="0.000164" iyy="0.0028805" iyz="0.0000075" izz="0.0007013"/>
    </inertial>
    <visual>
      <origin xyz="0.73175 -0.1040699 0.0010801" rpy="0.0000001 -0. -1.5707961"/>
      <geometry>
        <mesh filename="file:///home/ubt/Documents/gitlab/images/ecbg/assets/meshes/R_ankle_roll_link_ankle_roll_01.obj" scale="1. 1. 1."/>
      </geometry>
    </visual>
    <visual>
      <origin xyz="-0.034 -0. 0.045" rpy="-0. -0.0000001 0.0000002"/>
      <geometry>
        <box size="0.03 0.12 0.26"/>
      </geometry>
    </visual>
    <collision>
      <origin xyz="-0.034 -0. 0.045" rpy="-0. -0.0000001 0.0000002"/>
      <geometry>
        <box size="0.03 0.12 0.26"/>
      </geometry>
    </collision>
  </link>
  <link name="R_elbow_roll_link">
    <inertial>
      <origin xyz="0.0083606 -0.0579 -0.0006582" rpy="0. 0. 0."/>
      <mass value="0.68337"/>
      <inertia ixx="0.0025998" ixy="0.0002975" ixz="-0.0000051" iyy="0.0014326" iyz="0.0000264" izz="0.0022487"/>
    </inertial>
    <visual>
      <origin xyz="-0.2671447 -0.3062891 0.0427078" rpy="-3.1201072 -0.1732188 3.017554 "/>
      <geometry>
        <mesh filename="file:///home/ubt/Documents/gitlab/images/ecbg/assets/meshes/elbow_roll_01.obj" scale="1. 1. 1."/>
      </geometry>
    </visual>
  </link>
  <link name="R_elbow_yaw_link">
    <inertial>
      <origin xyz="-0.0009741 -0.0001792 0.045777 " rpy="0. 0. 0."/>
      <mass value="0.87457"/>
      <inertia ixx="0.0014384" ixy="0.0000039" ixz="0.0000522" iyy="0.00164" iyz="-0.0000007" izz="0.0008758"/>
    </inertial>
    <visual>
      <origin xyz="-0.2919612 -0.0038574 0.2053104" rpy="-1.5707964 0.1221731 3.1415927"/>
      <geometry>
        <mesh filename="file:///home/ubt/Documents/gitlab/images/ecbg/assets/meshes/elbow_yaw_01.obj" scale="1. 1. 1."/>
      </geometry>
    </visual>
  </link>
  <link name="R_hip_pitch_link">
    <inertial>
      <origin xyz="0.0015213 -0.15561 0.0027829" rpy="0. 0. 0."/>
      <mass value="4.1557999"/>
      <inertia ixx="0.042874" ixy="0.0019094" ixz="-0.0000843" iyy="0.010002" iyz="0.00113" izz="0.042717"/>
    </inertial>
    <visual>
      <origin xyz="-0.0000004 0.0063413 -0.1051548" rpy="-1.5707957 1.5707961 -1.5707957"/>
      <geometry>
        <mesh filename="file:///home/ubt/Documents/gitlab/images/ecbg/assets/meshes/R_hip_pitch_01.obj" scale="1. 1. 1."/>
      </geometry>
    </visual>
  </link>
  <link name="R_hip_roll_link">
    <inertial>
      <origin xyz="0.0092362 0.0006846 -0.0076246" rpy="0. 0. 0."/>
      <mass value="1.3211"/>
      <inertia ixx="0.001866" ixy="0.0000152" ixz="-0.000098" iyy="0.0017359" iyz="0.0000252" izz="0.0011634"/>
    </inertial>
    <visual>
      <origin xyz="-0.0999989 -0.1054735 0.0000682" rpy="0.0000001 0. -1.5707964"/>
      <geometry>
        <mesh filename="file:///home/ubt/Documents/gitlab/images/ecbg/assets/meshes/R_hip_roll_link_L_hip_roll_01.obj" scale="1. 1. 1."/>
      </geometry>
    </visual>
  </link>
  <link name="R_hip_yaw_link">
    <inertial>
      <origin xyz="0.0002397 0.0039636 0.11569 " rpy="0. 0. 0."/>
      <mass value="2.2890999"/>
      <inertia ixx="0.0043044" ixy="0.000004" ixz="-0.0000092" iyy="0.0048929" iyz="-0.000051" izz="0.0036277"/>
    </inertial>
    <visual>
      <origin xyz="-0.0007788 0.1054078 0.1236935" rpy="-1.5707964 -0. 1.5707964"/>
      <geometry>
        <mesh filename="file:///home/ubt/Documents/gitlab/images/ecbg/assets/meshes/R_hip_yaw_link_hip_yaw_01.obj" scale="1. 1. 1."/>
      </geometry>
    </visual>
  </link>
  <link name="R_knee_pitch_link">
    <inertial>
      <origin xyz="-0.0010047 -0.15955 0.0010045" rpy="0. 0. 0."/>
      <mass value="3.8269"/>
      <inertia ixx="0.034069" ixy="-0.000889" ixz="-0.0000685" iyy="0.0048648" iyz="-0.000151" izz="0.034816"/>
    </inertial>
    <visual>
      <origin xyz="-0.0000017 0.3606651 -0.1053768" rpy="0. 1.5707964 0. "/>
      <geometry>
        <mesh filename="file:///home/ubt/Documents/gitlab/images/ecbg/assets/meshes/R_knee_pitch_01.obj" scale="1. 1. 1."/>
      </geometry>
    </visual>
  </link>
  <link name="R_shoulder_pitch_link">
    <inertial>
      <origin xyz="-0.0000887 0.0050444 -0.052623 " rpy="0. 0. 0."/>
      <mass value="0.98273"/>
      <inertia ixx="0.0011778" ixy="-0.0000052" ixz="-0.0000046" iyy="0.0011244" iyz="0.0000315" izz="0.0009029"/>
    </inertial>
    <visual>
      <origin xyz="0.6308611 -0.0113187 0.1489976" rpy="1.5707964 -1.5707964 0. "/>
      <geometry>
        <mesh filename="file:///home/ubt/Documents/gitlab/images/ecbg/assets/meshes/should_pitch_01.obj" scale="1. 1. 1."/>
      </geometry>
    </visual>
  </link>
  <link name="R_shoulder_roll_link">
    <inertial>
      <origin xyz="-0.036091 0.0019662 0.0053449" rpy="0. 0. 0."/>
      <mass value="0.5434"/>
      <inertia ixx="0.0012461" ixy="-0.0000187" ixz="-0.000109" iyy="0.001912" iyz="0.000013" izz="0.0014368"/>
    </inertial>
    <visual>
      <origin xyz="-0.6028796 -0.2866124 -0.0029446" rpy="-0. 0. -1.4486233"/>
      <geometry>
        <mesh filename="file:///home/ubt/Documents/gitlab/images/ecbg/assets/meshes/should_roll_01.obj" scale="1. 1. 1."/>
      </geometry>
    </visual>
  </link>
  <link name="R_shoulder_yaw_link">
    <inertial>
      <origin xyz="-0.0090557 -0.0029797 0.12863 " rpy="0. 0. 0."/>
      <mass value="1.9965"/>
      <inertia ixx="0.015641" ixy="-0.0000494" ixz="0.0015722" iyy="0.015751" iyz="0.000468" izz="0.0021093"/>
    </inertial>
    <visual>
      <origin xyz="-0.2874316 0.0025429 0.516845 " rpy="-1.5707964 0.1221731 3.1415927"/>
      <geometry>
        <mesh filename="file:///home/ubt/Documents/gitlab/images/ecbg/assets/meshes/should_yaw_01.obj" scale="1. 1. 1."/>
      </geometry>
    </visual>
  </link>
  <link name="R_sixforce_link">
    <inertial>
      <origin xyz="-0.0001862 -0.0000021 -0.011066 " rpy="0. 0. 0."/>
      <mass value="0.17"/>
      <inertia ixx="0.0000357" ixy="0.0000002" ixz="0.0000008" iyy="0.0000503" iyz="-0.0000001" izz="0.0000613"/>
    </inertial>
  </link>
  <link name="R_wrist_pitch_link">
    <inertial>
      <origin xyz="-0.038445 0.0048559 0.0047721" rpy="0. 0. 0."/>
      <mass value="1.3145"/>
      <inertia ixx="0.0009004" ixy="0.000219" ixz="-0.0002271" iyy="0.0027314" iyz="0.0000305" izz="0.0027358"/>
    </inertial>
    <visual>
      <origin xyz="-0.0826179 0.0000045 0.2947486" rpy="-1.5707959 -1.4486232 -0.0000003"/>
      <geometry>
        <mesh filename="file:///home/ubt/Documents/gitlab/images/ecbg/assets/meshes/wrist_pitch_01.obj" scale="1. 1. 1."/>
      </geometry>
    </visual>
  </link>
  <link name="R_wrist_roll_link">
    <inertial>
      <origin xyz="0.0000046 0.017056 0.0007487" rpy="0. 0. 0."/>
      <mass value="0.1521"/>
      <inertia ixx="0.0002736" ixy="-0." ixz="-0." iyy="0.0002155" iyz="0.0000077" izz="0.0001102"/>
    </inertial>
    <visual>
      <origin xyz="-0.2954953 0.0105617 0.0000044" rpy="-0.0000001 0. -3.0194194"/>
      <geometry>
        <mesh filename="file:///home/ubt/Documents/gitlab/images/ecbg/assets/meshes/wrist_roll_01.obj" scale="1. 1. 1."/>
      </geometry>
    </visual>
  </link>
  <link name="back_rear_cam_Camera"/>
  <link name="base_link_body_imu_body_imu"/>
  <link name="head_fisheye_left_Camera"/>
  <link name="head_fisheye_right_Camera"/>
  <link name="head_pitch_link">
    <inertial>
      <origin xyz="0.040566 0.1025 -0.0002604" rpy="0. 0. 0."/>
      <mass value="1.069"/>
      <inertia ixx="0.0047354" ixy="0.0003344" ixz="-0.0000126" iyy="0.0045081" iyz="-0.0000268" izz="0.0051857"/>
    </inertial>
    <visual>
      <origin xyz="-0.005 -0.7727805 0.0000028" rpy="0. 1.5707963 0. "/>
      <geometry>
        <mesh filename="file:///home/ubt/Documents/gitlab/images/ecbg/assets/meshes/head_pitch_01.obj" scale="1. 1. 1."/>
      </geometry>
    </visual>
  </link>
  <link name="head_pitch_link_head_imu_head_imu"/>
  <link name="head_stereo_left_Camera_01"/>
  <link name="head_stereo_right_Camera_01"/>
  <link name="head_yaw_link">
    <inertial>
      <origin xyz="0.0002335 -0.0000398 0.023081 " rpy="0. 0. 0."/>
      <mass value="0.21952"/>
      <inertia ixx="0.0000812" ixy="0.000001" ixz="-0.0000003" iyy="0.0000629" iyz="0.0000038" izz="0.0000763"/>
    </inertial>
  </link>
  <link name="s2_v1">
    <visual>
      <origin xyz="0. 0. -0.1225744" rpy="1.5707964 0. 1.5707964"/>
      <geometry>
        <mesh filename="file:///home/ubt/Documents/gitlab/images/ecbg/assets/meshes/base_01.obj" scale="1. 1. 1."/>
      </geometry>
    </visual>
  </link>
  <link name="torso_link">
    <inertial>
      <origin xyz="0. 0. 0." rpy="0. 0. 0."/>
      <mass value="0.0001"/>
      <inertia ixx="0." ixy="0." ixz="0." iyy="0." iyz="0." izz="0."/>
    </inertial>
  </link>
  <link name="waist_front_cam_Camera"/>
  <link name="waist_pitch_link">
    <inertial>
      <origin xyz="-0.017372 0.20542 -0.0021071" rpy="0. 0. 0."/>
      <mass value="24.1860008"/>
      <inertia ixx="0.52255" ixy="0.0122" ixz="0.0024557" iyy="0.20002" iyz="-0.00535" izz="0.4671"/>
    </inertial>
    <visual>
      <origin xyz="0. -0.2649926 0.000001 " rpy="0. 1.5707963 0. "/>
      <geometry>
        <mesh filename="file:///home/ubt/Documents/gitlab/images/ecbg/assets/meshes/waist_pitch_01.obj" scale="1. 1. 1."/>
      </geometry>
    </visual>
  </link>
  <link name="waist_yaw_link">
    <inertial>
      <origin xyz="-0.0001989 -0.0096767 0.027108 " rpy="0. 0. 0."/>
      <mass value="0.51684"/>
      <inertia ixx="0.0017194" ixy="0.0000024" ixz="0.0000096" iyy="0.0010836" iyz="-0.0000649" izz="0.0013879"/>
    </inertial>
    <visual>
      <origin xyz="0. 0. 0.2652351" rpy="-1.5707964 0. 1.5707964"/>
      <geometry>
        <mesh filename="file:///home/ubt/Documents/gitlab/images/ecbg/assets/meshes/waist_yaw_01.obj" scale="1. 1. 1."/>
      </geometry>
    </visual>
  </link>
</robot>
